Workbook

Sheet dimDate
A1: Date | B1: Calendar Year | C1: Month Name | D1: Month Number | E1: Weekday | F1: Weekday number | G1: Quarter | H1: Month Sort | I1: Month Year | J1: MonthOffset | K1: Quarter Number | L1: Quarter Year | M1: Quarter Start Date | N1: Quarter Sort | O1: QuarterOffset
A2: 46002 | B2: 2025 | C2: December | D2: 12 | E2: Thursday | F2: 5 | G2: Q4 | H2: 24312 | I2: 45992 | J2: 7 | K2: 4 | L2: 2025 Q4 | M2: 45931 | N2: 8104 | O2: 3
A3: 46001 | B3: 2025 | C3: December | D3: 12 | E3: Wednesday | F3: 4 | G3: Q4 | H3: 24312 | I3: 45992 | J3: 7 | K3: 4 | L3: 2025 Q4 | M3: 45931 | N3: 8104 | O3: 3
A4: 46000 | B4: 2025 | C4: December | D4: 12 | E4: Tuesday | F4: 3 | G4: Q4 | H4: 24312 | I4: 45992 | J4: 7 | K4: 4 | L4: 2025 Q4 | M4: 45931 | N4: 8104 | O4: 3
A5: 45999 | B5: 2025 | C5: December | D5: 12 | E5: Monday | F5: 2 | G5: Q4 | H5: 24312 | I5: 45992 | J5: 7 | K5: 4 | L5: 2025 Q4 | M5: 45931 | N5: 8104 | O5: 3
A6: 45998 | B6: 2025 | C6: December | D6: 12 | E6: Sunday | F6: 1 | G6: Q4 | H6: 24312 | I6: 45992 | J6: 7 | K6: 4 | L6: 2025 Q4 | M6: 45931 | N6: 8104 | O6: 3
A7: 45997 | B7: 2025 | C7: December | D7: 12 | E7: Saturday | F7: 7 | G7: Q4 | H7: 24312 | I7: 45992 | J7: 7 | K7: 4 | L7: 2025 Q4 | M7: 45931 | N7: 8104 | O7: 3
A8: 45996 | B8: 2025 | C8: December | D8: 12 | E8: Friday | F8: 6 | G8: Q4 | H8: 24312 | I8: 45992 | J8: 7 | K8: 4 | L8: 2025 Q4 | M8: 45931 | N8: 8104 | O8: 3
A9: 45995 | B9: 2025 | C9: December | D9: 12 | E9: Thursday | F9: 5 | G9: Q4 | H9: 24312 | I9: 45992 | J9: 7 | K9: 4 | L9: 2025 Q4 | M9: 45931 | N9: 8104 | O9: 3
A10: 45994 | B10: 2025 | C10: December | D10: 12 | E10: Wednesday | F10: 4 | G10: Q4 | H10: 24312 | I10: 45992 | J10: 7 | K10: 4 | L10: 2025 Q4 | M10: 45931 | N10: 8104 | O10: 3
A11: 45993 | B11: 2025 | C11: December | D11: 12 | E11: Tuesday | F11: 3 | G11: Q4 | H11: 24312 | I11: 45992 | J11: 7 | K11: 4 | L11: 2025 Q4 | M11: 45931 | N11: 8104 | O11: 3
A12: 45992 | B12: 2025 | C12: December | D12: 12 | E12: Monday | F12: 2 | G12: Q4 | H12: 24312 | I12: 45992 | J12: 7 | K12: 4 | L12: 2025 Q4 | M12: 45931 | N12: 8104 | O12: 3
A13: 45991 | B13: 2025 | C13: November | D13: 11 | E13: Sunday | F13: 1 | G13: Q4 | H13: 24311 | I13: 45962 | J13: 8 | K13: 4 | L13: 2025 Q4 | M13: 45931 | N13: 8104 | O13: 3
... A101: 45903 | B101: 2025 | C101: September | D101: 9 | E101: Wednesday | F101: 4 | G101: Q3 | H101: 24309 | I101: 45901 | J101: 10 | K101: 3 | L101: 2025 Q3 | M101: 45839 | N101: 8103 | O101: 4

Sheet Activity Codes
A1: CODE | B1: REPORTING CATEGORY | C1: ACTIVITY CODE NAME
A2: 002 | B2: Basic Career Service (Self-Service) | C2: Self-Service AJCC Employment and Workforce Information Service
A3: 004 | B3: Basic Career Service (Self-Service) | C3: Self-Service Information on Training Providers/Performance Outcomes
A4: 005 | B4: Basic Career Service (Self-Service) | C4: Self-Service Labor Market Research
A5: 006 | B5: Basic Career Service (Self-Service) | C5: Self-Service Job Search through CalJOBS
A6: 06M | B6: Basic Career Service (Self-Service) | C6: Self-Service Job Search through Mobile App
A7: 007 | B7: Basic Career Service (Self-Service) | C7: Self-Service Initial Resume
A8: 008 | B8: Basic Career Service (Self-Service) | C8: Self-Service Resume: Update and Additions
A9: 010 | B9: Housekeeping | C9: Tracking Co-funded Services
A10: 050 | B10: Basic Career Service (Self-Service) | C10: Information on DI or PFL
A11: 051 | B11: Basic Career Service (Self-Service) | C11: Information on Social Services Programs
A12: 052 | B12: Basic Career Service (Self-Service) | C12: Information on other Public Assistance Programs
... A255: F22 | B255: Follow-up | C255: Supportive Service: Postsecondary Educational Materials

Sheet Participants
A1: EXIT DATE | B1: LWDB | C1: RESPONSIBLE OFFICE | D1: PARTICIPATION DATE | E1: GRANT ENROLL DATE | F1: LAST GRANT ACTIVITY DATE | G1: PROJECTED GRANT ACTIVITY END DATE | H1: RECEIVED CREDENTIAL | I1: ENTERED EMPLOYMENT | J1: WITH DISABILITY | K1: APP ID
B2: 29 | C2: =IFERROR(INDEX(Regions!$A$2:$A$19,MATCH(B2,Regions!$B$2:$B$19,0))&" Workforce Center","") -> Grand Meadow Workforce Center | D2: 46233 | E2: 46233 | F2: 46233 | G2: 46233 | H2: N | I2: N | J2: Y | K2: 1
B3: 12 | C3: =IFERROR(INDEX(Regions!$A$2:$A$19,MATCH(B3,Regions!$B$2:$B$19,0))&" Workforce Center","") -> Lakebridge Workforce Center | D3: 46233 | E3: 46233 | F3: 46233 | G3: 46233 | H3: N | I3: N | J3: Y | K3: 6
B4: 20 | C4: =IFERROR(INDEX(Regions!$A$2:$A$19,MATCH(B4,Regions!$B$2:$B$19,0))&" Workforce Center","") -> Rivermoor Workforce Center | D4: 46233 | E4: 46233 | F4: 46233 | G4: 46233 | H4: N | I4: N | J4: Y | K4: 1
B5: 43 | C5: =IFERROR(INDEX(Regions!$A$2:$A$19,MATCH(B5,Regions!$B$2:$B$19,0))&" Workforce Center","") -> Stonefield Workforce Center | D5: 46225 | E5: 46233 | F5: 46233 | G5: 46233 | H5: N | I5: N | J5: Y | K5: 1
B6: 29 | C6: =IFERROR(INDEX(Regions!$A$2:$A$19,MATCH(B6,Regions!$B$2:$B$19,0))&" Workforce Center","") -> Grand Meadow Workforce Center | D6: 46232 | E6: 46233 | F6: 46233 | G6: 46233 | H6: N | I6: N | J6: N | K6: 1
B7: 8 | C7: =IFERROR(INDEX(Regions!$A$2:$A$19,MATCH(B7,Regions!$B$2:$B$19,0))&" Workforce Center","") -> Amberfield Workforce Center | D7: 46232 | E7: 46232 | F7: 46232 | G7: 46232 | H7: N | I7: N | J7: N | K7: 1
B8: 32 | C8: =IFERROR(INDEX(Regions!$A$2:$A$19,MATCH(B8,Regions!$B$2:$B$19,0))&" Workforce Center","") -> Silver Creek Workforce Center | D8: 45978 | E8: 46230 | F8: 46230 | G8: 46230 | H8: N | I8: N | J8: N | K8: 1
B9: 33 | C9: =IFERROR(INDEX(Regions!$A$2:$A$19,MATCH(B9,Regions!$B$2:$B$19,0))&" Workforce Center","") -> Redstone Workforce Center | D9: 46227 | E9: 46227 | F9: 46227 | G9: 46227 | H9: N | I9: N | J9: Y | K9: 1
B10: 8 | C10: =IFERROR(INDEX(Regions!$A$2:$A$19,MATCH(B10,Regions!$B$2:$B$19,0))&" Workforce Center","") -> Amberfield Workforce Center | D10: 46226 | E10: 46226 | F10: 46232 | G10: 46232 | H10: N | I10: N | J10: N | K10: 1
B11: 12 | C11: =IFERROR(INDEX(Regions!$A$2:$A$19,MATCH(B11,Regions!$B$2:$B$19,0))&" Workforce Center","") -> Lakebridge Workforce Center | D11: 46226 | E11: 46226 | F11: 46226 | G11: 46226 | H11: N | I11: N | J11: Y | K11: 4
B12: 22 | C12: =IFERROR(INDEX(Regions!$A$2:$A$19,MATCH(B12,Regions!$B$2:$B$19,0))&" Workforce Center","") -> Pine Hollow Workforce Center | D12: 46226 | E12: 46226 | F12: 46226 | G12: 46226 | H12: N | I12: N | J12: Y | K12: 1
B13: 20 | C13: =IFERROR(INDEX(Regions!$A$2:$A$19,MATCH(B13,Regions!$B$2:$B$19,0))&" Workforce Center","") -> Rivermoor Workforce Center | D13: 46164 | E13: 46225 | F13: 46225 | G13: 46225 | H13: N | I13: N | J13: Y | K13: 1
B14: 29 | C14: =IFERROR(INDEX(Regions!$A$2:$A$19,MATCH(B14,Regions!$B$2:$B$19,0))&" Workforce Center","") -> Grand Meadow Workforce Center | D14: 46223 | E14: 46225 | F14: 46225 | G14: 46225 | H14: N | I14: N | J14: Y | K14: 1
B15: 8 | C15: =IFERROR(INDEX(Regions!$A$2:$A$19,MATCH(B15,Regions!$B$2:$B$19,0))&" Workforce Center","") -> Amberfield Workforce Center | D15: 46205 | E15: 46224 | G15: 46598 | H15: N | I15: N | J15: Y | K15: 1
B16: 48 | C16: =IFERROR(INDEX(Regions!$A$2:$A$19,MATCH(B16,Regions!$B$2:$B$19,0))&" Workforce Center","") -> Westhaven Workforce Center | D16: 46223 | E16: 46223 | F16: 46223 | G16: 46223 | H16: N | I16: N | J16: Y | K16: 1
B17: 42 | C17: =IFERROR(INDEX(Regions!$A$2:$A$19,MATCH(B17,Regions!$B$2:$B$19,0))&" Workforce Center","") -> Willow Bend Workforce Center | D17: 46209 | E17: 46220 | F17: 46220 | G17: 46220 | H17: N | I17: N | J17: Y | K17: 1
B18: 35 | C18: =IFERROR(INDEX(Regions!$A$2:$A$19,MATCH(B18,Regions!$B$2:$B$19,0))&" Workforce Center","") -> Elm Harbor Workforce Center | D18: 46220 | E18: 46220 | F18: 46220 | G18: 46220 | H18: N | I18: N | J18: Y | K18: 1
B19: 35 | C19: =IFERROR(INDEX(Regions!$A$2:$A$19,MATCH(B19,Regions!$B$2:$B$19,0))&" Workforce Center","") -> Elm Harbor Workforce Center | D19: 46219 | E19: 46219 | F19: 46219 | G19: 46219 | H19: N | I19: N | J19: Y | K19: 1
B20: 29 | C20: =IFERROR(INDEX(Regions!$A$2:$A$19,MATCH(B20,Regions!$B$2:$B$19,0))&" Workforce Center","") -> Grand Meadow Workforce Center | D20: 46218 | E20: 46219 | F20: 46219 | G20: 46219 | H20: N | I20: N | J20: Y | K20: 1
B21: 33 | C21: =IFERROR(INDEX(Regions!$A$2:$A$19,MATCH(B21,Regions!$B$2:$B$19,0))&" Workforce Center","") -> Redstone Workforce Center | D21: 46219 | E21: 46219 | G21: 46255 | H21: N | I21: N | J21: Y | K21: 1
B22: 33 | C22: =IFERROR(INDEX(Regions!$A$2:$A$19,MATCH(B22,Regions!$B$2:$B$19,0))&" Workforce Center","") -> Redstone Workforce Center | D22: 46219 | E22: 46219 | F22: 46230 | G22: 46230 | H22: N | I22: N | J22: Y | K22: 1
B23: 8 | C23: =IFERROR(INDEX(Regions!$A$2:$A$19,MATCH(B23,Regions!$B$2:$B$19,0))&" Workforce Center","") -> Amberfield Workforce Center | D23: 46218 | E23: 46218 | F23: 46218 | G23: 46218 | H23: N | I23: N | J23: Y | K23: 1
B24: 28 | C24: =IFERROR(INDEX(Regions!$A$2:$A$19,MATCH(B24,Regions!$B$2:$B$19,0))&" Workforce Center","") -> Clearfork Workforce Center | D24: 46216 | E24: 46218 | F24: 46218 | G24: 46218 | H24: N | I24: N | J24: Y | K24: 1
B25: 22 | C25: =IFERROR(INDEX(Regions!$A$2:$A$19,MATCH(B25,Regions!$B$2:$B$19,0))&" Workforce Center","") -> Pine Hollow Workforce Center | D25: 46217 | E25: 46217 | F25: 46217 | G25: 46217 | H25: N | I25: N | J25: Y | K25: 1
B26: 42 | C26: =IFERROR(INDEX(Regions!$A$2:$A$19,MATCH(B26,Regions!$B$2:$B$19,0))&" Workforce Center","") -> Willow Bend Workforce Center | D26: 46209 | E26: 46217 | F26: 46217 | G26: 46217 | H26: N | I26: N | J26: Y | K26: 1
B27: 8 | C27: =IFERROR(INDEX(Regions!$A$2:$A$19,MATCH(B27,Regions!$B$2:$B$19,0))&" Workforce Center","") -> Amberfield Workforce Center | D27: 46176 | E27: 46217 | F27: 46231 | G27: 46231 | H27: N | I27: N | J27: Y | K27: 1
B28: 15 | C28: =IFERROR(INDEX(Regions!$A$2:$A$19,MATCH(B28,Regions!$B$2:$B$19,0))&" Workforce Center","") -> Maple Crossing Workforce Center | D28: 45369 | E28: 46217 | F28: 46217 | G28: 46217 | H28: N | I28: N | J28: Y | K28: 1
B29: 33 | C29: =IFERROR(INDEX(Regions!$A$2:$A$19,MATCH(B29,Regions!$B$2:$B$19,0))&" Workforce Center","") -> Redstone Workforce Center | D29: 46171 | E29: 46217 | F29: 46217 | G29: 46217 | H29: N | I29: N | J29: Y | K29: 1
B30: 33 | C30: =IFERROR(INDEX(Regions!$A$2:$A$19,MATCH(B30,Regions!$B$2:$B$19,0))&" Workforce Center","") -> Redstone Workforce Center | D30: 46213 | E30: 46216 | F30: 46217 | G30: 46217 | H30: N | I30: N | J30: Y | K30: 1
B31: 7 | C31: =IFERROR(INDEX(Regions!$A$2:$A$19,MATCH(B31,Regions!$B$2:$B$19,0))&" Workforce Center","") -> Prairie Glen Workforce Center | D31: 46216 | E31: 46216 | F31: 46227 | G31: 46227 | H31: N | I31: N | J31: Y | K31: 1
B32: 12 | C32: =IFERROR(INDEX(Regions!$A$2:$A$19,MATCH(B32,Regions!$B$2:$B$19,0))&" Workforce Center","") -> Lakebridge Workforce Center | D32: 46051 | E32: 46216 | F32: 46216 | G32: 46216 | H32: N | I32: N | J32: Y | K32: 1
B33: 45 | C33: =IFERROR(INDEX(Regions!$A$2:$A$19,MATCH(B33,Regions!$B$2:$B$19,0))&" Workforce Center","") -> Briar Lake Workforce Center | D33: 46216 | E33: 46216 | F33: 46216 | G33: 46216 | H33: N | I33: N | J33: Y | K33: 6
... B54: 33 | C54: =IFERROR(INDEX(Regions!$A$2:$A$19,MATCH(B54,Regions!$B$2:$B$19,0))&" Workforce Center","") -> Redstone Workforce Center | D54: 46205 | E54: 46205 | F54: 46205 | G54: 46205 | H54: N | I54: N | J54: Y | K54: 1
B55: 23 | C55: =IFERROR(INDEX(Regions!$A$2:$A$19,MATCH(B55,Regions!$B$2:$B$19,0))&" Workforce Center","") -> Oakmere Workforce Center | D55: 46204 | E55: 46204 | G55: 46477 | H55: N | I55: N | J55: Y | K55: 2
B56: 22 | C56: =IFERROR(INDEX(Regions!$A$2:$A$19,MATCH(B56,Regions!$B$2:$B$19,0))&" Workforce Center","") -> Pine Hollow Workforce Center | D56: 46204 | E56: 46204 | F56: 46217 | G56: 46217 | H56: N | I56: N | J56: N | K56: 1
B57: 33 | C57: =IFERROR(INDEX(Regions!$A$2:$A$19,MATCH(B57,Regions!$B$2:$B$19,0))&" Workforce Center","") -> Redstone Workforce Center | D57: 45953 | E57: 46204 | F57: 46204 | G57: 46204 | H57: N | I57: N | J57: Y | K57: 1
B58: 35 | C58: =IFERROR(INDEX(Regions!$A$2:$A$19,MATCH(B58,Regions!$B$2:$B$19,0))&" Workforce Center","") -> Elm Harbor Workforce Center | D58: 46204 | E58: 46204 | F58: 46204 | G58: 46204 | H58: N | I58: N | J58: Y | K58: 1
B59: 35 | C59: =IFERROR(INDEX(Regions!$A$2:$A$19,MATCH(B59,Regions!$B$2:$B$19,0))&" Workforce Center","") -> Elm Harbor Workforce Center | D59: 46120 | E59: 46204 | F59: 46204 | G59: 46204 | H59: N | I59: N | J59: Y | K59: 1
B60: 35 | C60: =IFERROR(INDEX(Regions!$A$2:$A$19,MATCH(B60,Regions!$B$2:$B$19,0))&" Workforce Center","") -> Elm Harbor Workforce Center | D60: 46132 | E60: 46204 | F60: 46204 | G60: 46204 | H60: N | I60: N | J60: Y | K60: 1
...

Sheet Regions
A1: REGION LWDB | B1: REGION CODE | C1: REGION SHORT ABBR
A2: Cedarhaven | B2: 1 | C2: CDH
A3: Lakebridge | B3: 12 | C3: LKB
A4: Prairie Glen | B4: 7 | C4: PRG
A5: Amberfield | B5: 8 | C5: AMF
A6: Rivermoor | B6: 20 | C6: RVM
A7: Oakmere | B7: 23 | C7: OKM
A8: Pine Hollow | B8: 22 | C8: PNH
A9: Clearfork | B9: 28 | C9: CLF
A10: Grand Meadow | B10: 29 | C10: GDM
A11: Silver Creek | B11: 32 | C11: SVC
A12: Redstone | B12: 33 | C12: RDS
A13: Elm Harbor | B13: 35 | C13: ELH
... A19: Meadowbrook | B19: 50 | C19: MDB

Sheet Targets
A1: ENROLLMENT TARGETS | B1: SUB CODE | C1: SITE | D1: REGION LWDB | E1: REGION CODE
A2: 30 | B2: CDH | C2: Cedarhaven | D2: Cedarhaven | E2: 1
A3: 40 | B3: BRL | C3: Briar Lake | D3: Briar Lake | E3: 45
A4: 40 | B4: AMF | C4: Amberfield | D4: Amberfield | E4: 8
A5: 50 | B5: CLF | C5: Clearfork | D5: Clearfork | E5: 130
A6: 50 | B6: WLB | C6: Willow Bend | D6: Willow Bend | E6: 42
A7: 50 | B7: MPC | C7: Maple Crossing | D7: Maple Crossing | E7: 15
A8: 70 | B8: STF | C8: Stonefield | D8: Stonefield | E8: 43
A9: 71 | B9: OKM | C9: Oakmere | D9: Oakmere | E9: 23
A10: 80 | B10: PNH | C10: Pine Hollow | D10: Pine Hollow | E10: 120
A11: 100 | B11: RVM | C11: Rivermoor | D11: Rivermoor | E11: 110
A12: 100 | B12: PRG | C12: Prairie Glen | D12: Prairie Glen | E12: 7
A13: 100 | B13: SVC | C13: Silver Creek | D13: Silver Creek | E13: 32
... A18: 150 | B18: RDS | C18: Redstone | D18: Redstone | E18: 140

Sheet Services
A1: OFFICE | B1: SERVICE | C1: COMPLETION STATUS | D1: PROGRAM | E1: PROVIDER | F1: CREATE DATE | G1: ACTUAL BEGIN DATE | H1: PROJECTED BEGIN DATE | I1: ACTUAL END DATE | J1: PROJECTED END DATE | K1: REGISTERED APPRENTICESHIP | L1: HISPANIC | M1: COMMENTS | N1: USER ID | O1: OFFICE OF RESPONSIBILITY | P1: NAICS | Q1: ONET | R1: TYPE OF APPRENTICESHIP | S1: REGION LWDB | T1: MOST RECENT EMPLOYMENT DATE | U1: LEARNING MODE | V1: AGENCY CODE | W1: SERVICE PROVIDED | X1: EX OFFENDER | Y1: SERVICE PREFIX | Z1: SERVICE CATEGORY | AA1: CATEGORY SORT | AB1: REGION CODE
A2: Pine Hollow Workforce Center | B2: 115 - Resume Preparation Assistance | C2: Successful Completion | D2: Adult/Dislocated Worker Core, Intensive and Follow-up Office Services | E2: PNH Workforce | F2: 46244 | G2: 46219 | H2: 46219 | I2: 46219 | J2: 46219 | K2: Not Disclose | L2: No | N2: 1 | O2: Pine Hollow Workforce Center | S2: Pine Hollow | U2: No Virtual/Online, In-person Only | V2: D50 | W2: BASIC | X2: No | Y2: 115 | Z2: Basic Career Service (Staff-Assisted) | AA2: 30 | AB2: 22
A3: Pine Hollow Workforce Center | B3: 125 - Job Search and Placement Assistance | C3: Successful Completion | D3: Adult/Dislocated Worker Core, Intensive and Follow-up Office Services | E3: PNH Workforce | F3: 46244 | G3: 46226 | H3: 46226 | I3: 46226 | J3: 46226 | K3: Not Disclose | L3: No | N3: 1 | O3: Pine Hollow Workforce Center | S3: Pine Hollow | U3: No Virtual/Online, In-person Only | V3: D50 | W3: BASIC | X3: No | Y3: 125 | Z3: Basic Career Service (Staff-Assisted) | AA3: 30 | AB3: 22
A4: Pine Hollow Workforce Center | B4: 200 - Individual Counseling | C4: Successful Completion | D4: Other Office Services (Adult/Dislocated Worker) | E4: PNH Workforce | F4: 46244 | G4: 46224 | H4: 46224 | I4: 46224 | J4: 46224 | K4: Not Disclose | L4: No | N4: 1 | O4: Pine Hollow Workforce Center | S4: Pine Hollow | U4: No Virtual/Online, In-person Only | V4: D50 | W4: INDIVIDUAL SERVICES | X4: No | Y4: 200 | Z4: Individualized Career Service | AA4: 40 | AB4: 22
A5: Pine Hollow Workforce Center | B5: 125 - Job Search and Placement Assistance | C5: Successful Completion | D5: Adult/Dislocated Worker Core, Intensive and Follow-up Office Services | E5: PNH Workforce | F5: 46244 | G5: 46234 | H5: 46234 | I5: 46234 | J5: 46234 | K5: Not Disclose | L5: No | N5: 1 | O5: Pine Hollow Workforce Center | S5: Pine Hollow | U5: No Virtual/Online, In-person Only | V5: D50 | W5: BASIC | X5: No | Y5: 125 | Z5: Basic Career Service (Staff-Assisted) | AA5: 30 | AB5: 22
A6: Pine Hollow Workforce Center | B6: 189 - Supportive Service: Housing Assistance | C6: Successful Completion | D6: SS - Shelter | E6: PNH Workforce | F6: 46244 | G6: 46224 | H6: 46224 | I6: 46224 | J6: 46224 | K6: Not Disclose | L6: No | N6: 1 | O6: Pine Hollow Workforce Center | S6: Pine Hollow | U6: No Virtual/Online, In-person Only | V6: D50 | W6: 189 - Supportive Service: Housing Assistance | X6: No | Y6: 189 | Z6: Supportive Service | AA6: 70 | AB6: 22
A7: Grand Meadow Workforce Center | B7: 200 - Individual Counseling | C7: Successful Completion | D7: Individualized Career Services (Adult/DW) | E7: GDM Workforce | F7: 46241 | G7: 46231 | H7: 46231 | I7: 46231 | J7: 46231 | K7: Not Disclose | L7: No | N7: 1 | O7: Grand Meadow Workforce Center | S7: Grand Meadow | U7: No Virtual/Online, In-person Only | V7: 129 | W7: INDIVIDUAL SERVICES | X7: No | Y7: 200 | Z7: Individualized Career Service | AA7: 40 | AB7: 29
A8: Westhaven Workforce Center | B8: 101 - Orientation | C8: Successful Completion | E8: WST Workforce | F8: 46238 | G8: 46223 | I8: 46223 | J8: 46223 | K8: Not Disclose | L8: No | N8: 1 | O8: Westhaven Workforce Center | S8: Westhaven | U8: No Virtual/Online, In-person Only | V8: MCS | W8: BASIC | X8: No | Y8: 101 | Z8: Basic Career Service (Self-Service) | AA8: 20 | AB8: 48
A9: Westhaven Workforce Center | B9: 108 - Referred to WIOA Services (not training) | C9: Successful Completion | E9: WST Workforce | F9: 46238 | G9: 46223 | I9: 46223 | J9: 46223 | K9: Not Disclose | L9: No | N9: 1 | O9: Westhaven Workforce Center | S9: Westhaven | U9: No Virtual/Online, In-person Only | V9: MCS | W9: BASIC | X9: No | Y9: 108 | Z9: Basic Career Service (Staff-Assisted) | AA9: 30 | AB9: 48
A10: Silver Creek Workforce Center | B10: 112 - Job Fair | C10: Successful Completion | D10: Local Program | E10: SVC Workforce | F10: 46237 | G10: 46219 | H10: 46219 | I10: 46219 | J10: 46219 | K10: Not Disclose | L10: Yes | N10: 1 | O10: Silver Creek Workforce Center | S10: Silver Creek | U10: No Virtual/Online, In-person Only | V10: C01 | W10: BASIC | X10: No | Y10: 112 | Z10: Basic Career Service (Self-Service) | AA10: 20 | AB10: 32
A11: Pine Hollow Workforce Center | B11: 140 - Referred to Other Federal/State Assistance | C11: Successful Completion | D11: Adult/Dislocated Worker Core, Intensive and Follow-up Office Services | E11: PNH Workforce | F11: 46234 | G11: 46226 | H11: 46226 | I11: 46226 | J11: 46226 | K11: Not Disclose | L11: No | N11: 1 | O11: Pine Hollow Workforce Center | S11: Pine Hollow | U11: No Virtual/Online, In-person Only | V11: D60 | W11: 140 - Referred to Other Federal/State Assistance | X11: No | Y11: 140 | Z11: Basic Career Service (Staff-Assisted) | AA11: 30 | AB11: 22
A12: Pine Hollow Workforce Center | B12: 108 - Referred to WIOA Services (not training) | C12: Successful Completion | D12: Adult/Dislocated Worker Core, Intensive and Follow-up Office Services | E12: PNH Workforce | F12: 46234 | G12: 46226 | H12: 46226 | I12: 46226 | J12: 46226 | K12: Not Disclose | L12: No | N12: 1 | O12: Pine Hollow Workforce Center | S12: Pine Hollow | U12: No Virtual/Online, In-person Only | V12: D60 | W12: BASIC | X12: No | Y12: 108 | Z12: Basic Career Service (Staff-Assisted) | AA12: 30 | AB12: 22
A13: Pine Hollow Workforce Center | B13: 102 - Initial Assessment | C13: Successful Completion | D13: Adult/Dislocated Worker Core, Intensive and Follow-up Office Services | E13: PNH Workforce | F13: 46234 | G13: 46226 | H13: 46226 | I13: 46226 | J13: 46226 | K13: Not Disclose | L13: No | N13: 1 | O13: Pine Hollow Workforce Center | S13: Pine Hollow | U13: No Virtual/Online, In-person Only | V13: D60 | W13: BASIC | X13: No | Y13: 102 | Z13: Basic Career Service (Staff-Assisted) | AA13: 30 | AB13: 22
A14: Pine Hollow Workforce Center | B14: 101 - Orientation | C14: Successful Completion | D14: Adult/Dislocated Worker Core, Intensive and Follow-up Office Services | E14: PNH Workforce | F14: 46234 | G14: 46226 | H14: 46226 | I14: 46226 | J14: 46226 | K14: Not Disclose | L14: No | N14: 1 | O14: Pine Hollow Workforce Center | S14: Pine Hollow | U14: No Virtual/Online, In-person Only | V14: D60 | W14: BASIC | X14: No | Y14: 101 | Z14: Basic Career Service (Self-Service) | AA14: 20 | AB14: 22
A15: Silver Creek Workforce Center | B15: 202 - Career Guidance/Planning | C15: Successful Completion | D15: Local Program | E15: SVC Workforce | F15: 46234 | G15: 46230 | H15: 46230 | I15: 46230 | J15: 46230 | K15: Not Disclose | L15: No | N15: 1 | O15: Silver Creek Workforce Center | S15: Silver Creek | U15: No Virtual/Online, In-person Only | V15: C01 | W15: INDIVIDUAL SERVICES | X15: No | Y15: 202 | Z15: Individualized Career Service | AA15: 40 | AB15: 32
A16: Grand Meadow Workforce Center | B16: 102 - Initial Assessment | C16: Successful Completion | D16: Basic Career Services (Adult/DW) | E16: GDM Workforce | F16: 46234 | G16: 46233 | H16: 46233 | I16: 46233 | J16: 46233 | K16: Not Disclose | L16: Information Not Provided | N16: 1 | O16: Grand Meadow Workforce Center | S16: Grand Meadow | U16: No Virtual/Online, In-person Only | V16: 129 | W16: BASIC | X16: No | Y16: 102 | Z16: Basic Career Service (Staff-Assisted) | AA16: 30 | AB16: 29
A17: Lakebridge Workforce Center | B17: 200 - Individual Counseling | C17: Successful Completion | E17: LKB Workforce | F17: 46233 | G17: 46233 | I17: 46233 | J17: 46233 | K17: Not Disclose | L17: No | N17: 1 | O17: Lakebridge Workforce Center | S17: Lakebridge | U17: No Virtual/Online, In-person Only | W17: INDIVIDUAL SERVICES | X17: No | Y17: 200 | Z17: Individualized Career Service | AA17: 40 | AB17: 12
A18: Prairie Glen Workforce Center | B18: 200 - Individual Counseling | C18: Successful Completion | D18: Other Office Services | E18: PRG Workforce | F18: 46233 | G18: 46233 | I18: 46233 | J18: 46233 | K18: Not Disclose | L18: No | N18: 1 | O18: Prairie Glen Workforce Center | S18: Prairie Glen | T18: 46209 | U18: No Virtual/Online, In-person Only | V18: GSC1 | W18: INDIVIDUAL SERVICES | X18: No | Y18: 200 | Z18: Individualized Career Service | AA18: 40 | AB18: 7
A19: Lakebridge Workforce Center | B19: 185 - Supportive Service: Other | C19: Successful Completion | E19: LKB Workforce | F19: 46233 | G19: 46233 | I19: 46233 | J19: 46233 | K19: Not Disclose | L19: No | N19: 1 | O19: Lakebridge Workforce Center | S19: Lakebridge | U19: No Virtual/Online, In-person Only | W19: INDIVIDUAL SERVICES | X19: No | Y19: 185 | Z19: Supportive Service | AA19: 70 | AB19: 12
A20: Prairie Glen Workforce Center | B20: 185 - Supportive Service: Other | C20: Successful Completion | D20: Supportive Service - Other | E20: PRG Workforce | F20: 46233 | G20: 46233 | I20: 46233 | J20: 46233 | K20: Not Disclose | L20: No | N20: 1 | O20: Prairie Glen Workforce Center | S20: Prairie Glen | T20: 46209 | U20: No Virtual/Online, In-person Only | V20: GSC1 | W20: INDIVIDUAL SERVICES | X20: No | Y20: 185 | Z20: Supportive Service | AA20: 70 | AB20: 7
A21: Westhaven Workforce Center | B21: 202 - Career Guidance/Planning | C21: Successful Completion | E21: WST Workforce | F21: 46232 | G21: 46220 | I21: 46220 | J21: 46220 | K21: Not Disclose | L21: No | N21: 1 | O21: Westhaven Workforce Center | S21: Westhaven | U21: No Virtual/Online, In-person Only | V21: MCS | W21: INDIVIDUAL SERVICES | X21: Yes | Y21: 202 | Z21: Individualized Career Service | AA21: 40 | AB21: 48
A22: Westhaven Workforce Center | B22: 202 - Career Guidance/Planning | C22: Successful Completion | E22: WST Workforce | F22: 46232 | G22: 46220 | I22: 46220 | J22: 46220 | K22: Not Disclose | L22: Yes | N22: 1 | O22: Westhaven Workforce Center | S22: Westhaven | U22: Virtual/Online (Yes) | V22: MCS | W22: INDIVIDUAL SERVICES | X22: No | Y22: 202 | Z22: Individualized Career Service | AA22: 40 | AB22: 48
A23: Grand Meadow Workforce Center | B23: 200 - Individual Counseling | C23: Successful Completion | D23: Individualized Career Services (Adult/DW) | E23: GDM Workforce | F23: 46232 | G23: 46232 | H23: 46232 | I23: 46232 | J23: 46232 | K23: Not Disclose | L23: No | N23: 1 | O23: Grand Meadow Workforce Center | S23: Grand Meadow | T23: 46219 | U23: No Virtual/Online, In-person Only | V23: 129 | W23: INDIVIDUAL SERVICES | X23: No | Y23: 200 | Z23: Individualized Career Service | AA23: 40 | AB23: 29
A24: Westhaven Workforce Center | B24: 202 - Career Guidance/Planning | C24: Successful Completion | E24: WST Workforce | F24: 46232 | G24: 46220 | I24: 46220 | J24: 46220 | K24: Not Disclose | L24: Yes | N24: 3 | O24: Westhaven Workforce Center | S24: Westhaven | U24: No Virtual/Online, In-person Only | V24: MCS | W24: INDIVIDUAL SERVICES | X24: No | Y24: 202 | Z24: Individualized Career Service | AA24: 40 | AB24: 48
A25: Westhaven Workforce Center | B25: 202 - Career Guidance/Planning | C25: Successful Completion | E25: WST Workforce | F25: 46232 | G25: 46220 | I25: 46220 | J25: 46220 | K25: Not Disclose | L25: Yes | N25: 1 | O25: Westhaven Workforce Center | S25: Westhaven | U25: No Virtual/Online, In-person Only | V25: MCS | W25: INDIVIDUAL SERVICES | X25: Yes | Y25: 202 | Z25: Individualized Career Service | AA25: 40 | AB25: 48
A26: Grand Meadow Workforce Center | B26: 200 - Individual Counseling | C26: Successful Completion | D26: Individualized Career Services (Adult/DW) | E26: GDM Workforce | F26: 46232 | G26: 46232 | H26: 46232 | I26: 46232 | J26: 46232 | K26: Not Disclose | L26: Information Not Provided | N26: 1 | O26: Grand Meadow Workforce Center | S26: Grand Meadow | U26: No Virtual/Online, In-person Only | V26: 129 | W26: INDIVIDUAL SERVICES | X26: No | Y26: 200 | Z26: Individualized Career Service | AA26: 40 | AB26: 29
A27: Westhaven Workforce Center | B27: 202 - Career Guidance/Planning | C27: Successful Completion | E27: WST Workforce | F27: 46232 | G27: 46220 | I27: 46220 | J27: 46220 | K27: Not Disclose | L27: Information Not Provided | N27: 2 | O27: Westhaven Workforce Center | S27: Westhaven | U27: Virtual/Online (Yes) | V27: MCS | W27: INDIVIDUAL SERVICES | X27: No | Y27: 202 | Z27: Individualized Career Service | AA27: 40 | AB27: 48
A28: Westhaven Workforce Center | B28: 202 - Career Guidance/Planning | C28: Successful Completion | E28: WST Workforce | F28: 46232 | G28: 46220 | I28: 46220 | J28: 46220 | K28: Not Disclose | L28: No | N28: 2 | O28: Westhaven Workforce Center | S28: Westhaven | U28: Virtual/Online (Yes) | V28: MCS | W28: INDIVIDUAL SERVICES | X28: No | Y28: 202 | Z28: Individualized Career Service | AA28: 40 | AB28: 48
A29: Westhaven Workforce Center | B29: 202 - Career Guidance/Planning | C29: Successful Completion | E29: WST Workforce | F29: 46232 | G29: 46220 | I29: 46220 | J29: 46220 | K29: Not Disclose | L29: Yes | N29: 2 | O29: Westhaven Workforce Center | S29: Westhaven | U29: Virtual/Online (Yes) | V29: MCS | W29: INDIVIDUAL SERVICES | X29: Yes | Y29: 202 | Z29: Individualized Career Service | AA29: 40 | AB29: 48
A30: Pine Hollow Workforce Center | B30: 108 - Referred to WIOA Services (not training) | C30: Successful Completion | D30: Adult/Dislocated Worker Core, Intensive and Follow-up Office Services | E30: PNH Workforce | F30: 46231 | G30: 46216 | H30: 46216 | I30: 46216 | J30: 46216 | K30: Not Disclose | L30: No | N30: 1 | O30: Pine Hollow Workforce Center | S30: Pine Hollow | U30: No Virtual/Online, In-person Only | V30: D10 | W30: BASIC | X30: No | Y30: 108 | Z30: Basic Career Service (Staff-Assisted) | AA30: 30 | AB30: 22
A31: Westhaven Workforce Center | B31: 202 - Career Guidance/Planning | C31: Successful Completion | E31: WST Workforce | F31: 46231 | G31: 46220 | I31: 46220 | J31: 46220 | K31: Not Disclose | L31: Yes | N31: 1 | O31: Westhaven Workforce Center | S31: Westhaven | U31: Virtual/Online (Yes) | V31: MCS | W31: INDIVIDUAL SERVICES | X31: No | Y31: 202 | Z31: Individualized Career Service | AA31: 40 | AB31: 48
A32: Pine Hollow Workforce Center | B32: 102 - Initial Assessment | C32: Successful Completion | D32: Adult/Dislocated Worker Core, Intensive and Follow-up Office Services | E32: PNH Workforce | F32: 46231 | G32: 46216 | H32: 46216 | I32: 46216 | J32: 46216 | K32: Not Disclose | L32: No | N32: 1 | O32: Pine Hollow Workforce Center | S32: Pine Hollow | U32: No Virtual/Online, In-person Only | V32: D10 | W32: BASIC | X32: No | Y32: 102 | Z32: Basic Career Service (Staff-Assisted) | AA32: 30 | AB32: 22
A33: Grand Meadow Workforce Center | B33: 200 - Individual Counseling | C33: Successful Completion | D33: Individualized Career Services (Adult/DW) | E33: GDM Workforce | F33: 46231 | G33: 46231 | H33: 46231 | I33: 46231 | J33: 46231 | K33: Not Disclose | L33: No | N33: 1 | O33: Grand Meadow Workforce Center | S33: Grand Meadow | U33: No Virtual/Online, In-person Only | V33: 129 | W33: INDIVIDUAL SERVICES | X33: No | Y33: 200 | Z33: Individualized Career Service | AA33: 40 | AB33: 29
A34: Grand Meadow Workforce Center | B34: 200 - Individual Counseling | C34: Successful Completion | D34: Individualized Career Services (Adult/DW) | E34: GDM Workforce | F34: 46231 | G34: 46230 | H34: 46230 | I34: 46230 | J34: 46230 | K34: Not Disclose | L34: No | N34: 1 | O34: Grand Meadow Workforce Center | S34: Grand Meadow | U34: No Virtual/Online, In-person Only | V34: 129 | W34: INDIVIDUAL SERVICES | X34: No | Y34: 200 | Z34: Individualized Career Service | AA34: 40 | AB34: 29
A35: Westhaven Workforce Center | B35: 202 - Career Guidance/Planning | C35: Successful Completion | E35: WST Workforce | F35: 46231 | G35: 46220 | I35: 46220 | J35: 46220 | K35: Not Disclose | L35: Yes | N35: 2 | O35: Westhaven Workforce Center | S35: Westhaven | U35: Virtual/Online (Yes) | V35: MCS | W35: INDIVIDUAL SERVICES | X35: Yes | Y35: 202 | Z35: Individualized Career Service | AA35: 40 | AB35: 48
A36: Pine Hollow Workforce Center | B36: 140 - Referred to Other Federal/State Assistance | C36: Successful Completion | D36: Adult/Dislocated Worker Core, Intensive and Follow-up Office Services | E36: PNH Workforce | F36: 46231 | G36: 46216 | H36: 46216 | I36: 46216 | J36: 46216 | K36: Not Disclose | L36: No | N36: 1 | O36: Pine Hollow Workforce Center | S36: Pine Hollow | U36: No Virtual/Online, In-person Only | V36: D10 | W36: 140 - Referred to Other Federal/State Assistance | X36: No | Y36: 140 | Z36: Basic Career Service (Staff-Assisted) | AA36: 30 | AB36: 22
A37: Prairie Glen Workforce Center | B37: 125 - Job Search and Placement Assistance | C37: Successful Completion | D37: Local Office Services | E37: PRG Workforce | F37: 46231 | G37: 46231 | H37: 46231 | I37: 46231 | J37: 46231 | K37: Not Disclose | L37: Yes | N37: 1 | O37: Prairie Glen Workforce Center | S37: Prairie Glen | U37: No Virtual/Online, In-person Only | V37: GSC1 | W37: BASIC | X37: No | Y37: 125 | Z37: Basic Career Service (Staff-Assisted) | AA37: 30 | AB37: 7
A38: Pine Hollow Workforce Center | B38: 115 - Resume Preparation Assistance | C38: Successful Completion | D38: Adult/Dislocated Worker Core, Intensive and Follow-up Office Services | E38: PNH Workforce | F38: 46231 | G38: 46230 | H38: 46230 | I38: 46230 | J38: 46230 | K38: Not Disclose | L38: No | N38: 1 | O38: Pine Hollow Workforce Center | S38: Pine Hollow | U38: No Virtual/Online, In-person Only | V38: D10 | W38: BASIC | X38: No | Y38: 115 | Z38: Basic Career Service (Staff-Assisted) | AA38: 30 | AB38: 22
A39: Westhaven Workforce Center | B39: 202 - Career Guidance/Planning | C39: Successful Completion | E39: WST Workforce | F39: 46231 | G39: 46220 | I39: 46220 | J39: 46220 | K39: Not Disclose | L39: No | N39: 3 | O39: Westhaven Workforce Center | S39: Westhaven | U39: Virtual/Online (Yes) | V39: MCS | W39: INDIVIDUAL SERVICES | X39: No | Y39: 202 | Z39: Individualized Career Service | AA39: 40 | AB39: 48
A40: Pine Hollow Workforce Center | B40: 101 - Orientation | C40: Successful Completion | D40: Adult/Dislocated Worker Core, Intensive and Follow-up Office Services | E40: PNH Workforce | F40: 46231 | G40: 46216 | H40: 46216 | I40: 46216 | J40: 46216 | K40: Not Disclose | L40: No | N40: 1 | O40: Pine Hollow Workforce Center | S40: Pine Hollow | U40: No Virtual/Online, In-person Only | V40: D10 | W40: BASIC | X40: No | Y40: 101 | Z40: Basic Career Service (Self-Service) | AA40: 20 | AB40: 22
...
